Workbook

Sheet CAPA
B1: DISTRIBUIÇÃO COMANDOS
B2: REGIONAIS POR COMANDO | E2: ULTIMA ATUALIZAÇÃO: 06/10/2026
B3: DIVISÕES POR REGIONAIS
B4: LISTA GERAL | C4: Telefones Grau V
B5: *CMD REGIONAL I* | C5: *CMD REGIONAL II* | D5: *CMD REGIONAL III* | E5: *CMD REGIONAL IV* | F5: *CMD REGIONAL V*
B6: Representante: Alex | C6: Mundial: Naruê | D6: Representante: Véio | E6: Mundial: Diego | F6: Mundial: Naruê
B7: Cmd Brasil: Borges | C7: Cmd Brasil: Bardo | D7: Cmd Brasil: Bad | E7: Cmd Regional: Marcio | F7: Cmd Brasil: Acarlos
B8: Disciplina: Machete | C8: Disciplina: Ching | D8: Disciplina: Cidão | E8: Disciplina: Machete | F8: Disciplina: Ching
B9: Inteligência: Daniel | C9: Inteligência: Custódio | D9: Inteligência: Fico | E9: Inteligência: Custódio | F9: Inteligência: Chaves
B10: Adm Cmd: | C10: Adm Cmd: | D10: Adm Cmd: Jonnhy | E10: Adm Cmd: | F10: Adm Cmd: Cabelo
B11: Expansão: Tibão / Marmita | C11: Expansão: Tibão / Diego | D11: Expansão: Tibão / Edinho | E11: Expansão: Tibão / Kracoldo | F11: Expansão: Tibão / Noslek
B12: Comunicação: Barney | C12: Comunicação: Barney | D12: Comunicação: Cruvinel | E12: Comunicação: Barney | F12: Comunicação: Chris Jr
B13: Operacional: Eric | C13: Operacional: Roney / Invictus | D13: Operacional: Godoy / Machado | E13: Operacional: Ted / Alemão / Mão | F13: Operacional: Roney / Tozão
B14: Armas: Zimermam | C14: Armas: Carcará | D14: Armas: Gomes | E14: Armas: Giordane | F14: Armas: Cembra
B15: *CMD REGIONAL VI* | C15: *CMD REGIONAL VII* | D15: *CMD REGIONAL VIII* | E15: *CMD REGIONAL IX* | F15: *CMD REGIONAL X*
B16: Mundial: Kefir | C16: Mundial: Dabota | D16: Mundial: Kefir | E16: Mundial: Naruê | F16: Mundial: Roney
... B44: Armas: Augusto | C44: Armas: Scherk | D44: Armas: Dcarne | E44: Armas: Capitão | F44: Armas: Chico Doido
B45: *CMD REGIONAL XXI* | C45: *CMD REGIONAL XXII* | D45: *CMD REGIONAL XXIII* | F45: *CMD XXV*
B46: Mundial: Roney | C46: Representante: K | D46: Mundial: Dabota | F46: Mundial: Diego
B47: Cmd Regional: Puro Ódio | C47: Cmd Regional: Seu Nelson | D47: Cmd Brasil: Mion | F47: Cmd Regional: Molezinha
B48: Disciplina: Machete | C48: Disciplina: | D48: Disciplina: Coquinho | F48: Disciplina: Igão
B49: Inteligência: Roney | C49: Inteligência: Fico | D49: Inteligência: Zelde | F49: Inteligência: Chaves
B50: Adm Cmd: Mapola | C50: Adm Cmd Br: Sola | D50: Adm Cmd Br: Sola | F50: Adm Cmd Br: Dead
B51: Expansão: Tibão / Furlan | C51: Expansão: Tibão / Adeilson | D51: Expansão: Tibão / Kracoldo | F51: Expansão: Tibão / Fonseca
B52: Comunicação: Chris Jr | C52: Comunicação: | D52: Comunicação: | F52: Comunicação:
B53: Operacional: Viking | C53: Operacional: Ted / Ceirão | D53: Operacional: Roney / Lek | F53: Operacional: Mesquita
B54: Armas: Odin | C54: Armas: Magirus | D54: Armas: | F54: Armas: Rocha
B55: *CMD REGIONAL XXVI* | C55: *CMD REGIONAL XXVII* | D55: *CMD REGIONAL XXVIII* | E55: *CMD REGIONAL XXIX* | F55: *CMD REGIONAL XXX*
B56: Mundial: Monge | C56: Mundial: Bin | D56: Mundial: Eusimio | E56: Mundial: Eusimio | F56: Representante: K
B57: Cmd Regional: Fuse | C57: Cmd Regional: Donizete | D57: Cmd Brasil: Trigão | E57: Cmd Brasil: Marquinhos | F57: Cmd Brasil: André Meira
B58: Disciplina: | C58: Disciplina: Filipe | D58: Disciplina: Dantas | E58: Disciplina: Filipe | F58: Disciplina: Igão
B59: Inteligência: Chefão | C59: Inteligência: Dias | D59: Inteligência: Reis (Kaveira) | E59: Inteligência: Fico | F59: Inteligência: Beto
B60: Adm Cmd Br: Sola | C60: Adm Cmd: Brow | D60: Adm Cmd: Cabelo | E60: Adm Cmd: Hugo Melo | F60: Adm Cmd: Joohnny
B61: Expansão: Tibão / Bomba | C61: Expansão: Tibão / Fonseca | D61: Expansão: Tibão / Jeferson | E61: Expansão: Tibão / Sniper | F61: Expansão: Tibão / Adeilson
B62: Comunicação: | C62: Comunicação: Barney | D62: Comunicação: Chris Jr | E62: Comunicação: | F62: Comunicação: Chris Jr
B63: Operacional: Ted / Kratos | C63: Operacional: Ted / Danilo | D63: Operacional: Panda | E63: Operacional: Ted / Dias | F63: Operacional: Damásio
B64: Armas: Belloto | C64: Armas: Barba Branca | D64: Armas: Pocoyo | E64: Armas: Santinão | F64: Armas: Miro
B65: CMD REGIONAL XXXI | C65: CMD REGIONAL XXXII | D65: CMD REGIONAL XXXIII | E65: CMD REGIONAL XXXIV | F65: CMD REGIONAL XXXV
B66: Mundial: Roney | C66: Mundial: Baptista | D66: Mundial: Baptista | E66: Mundial: Bin | F66: Mundial: Dabota
... B114: Armas: Capitão | C114: Armas: Rocha | D114: Armas: Shrek | E114: Armas: Odin | F114: Armas: Santinão
...

Sheet GERAL
A1: 01 ao 10 >>>
A2: Comando Regional I | C2: Comando Regional II | E2: Comando Regional III | G2: Comando Regional IV | I2: Comando Regional V | K2: Comando Regional VI | M2: Comando Regional VII | O2: Comando Regional VIII | Q2: Comando Regional IX | S2: Comando Regional X
A3: REGIONAL RIO DE JANEIRO - RJ1 | C3: REGIONAL NORDESTE I | E3: REGIONAL FLORIANOPOLIS | G3: REGIONAL MANAUS | I3: REGIONAL LITORAL NORTE - SP | K3: REGIONAL BRAGANÇA | M3: REGIONAL PRESIDENTE PRUDENTE | O3: REGIONAL SP3 - LESTE | Q3: REGIONAL BRASÍLIA I - DF | S3: REGIONAL OSASCO 1 - SP
A4: REGIONAL RIO DE JANEIRO - RJ1 | B4: Divisão Centro - RJ1 | C4: REGIONAL NORDESTE I | D4: Divisão Ibiapina - CE | E4: REGIONAL FLORIANOPOLIS | F4: Divisão Criciúma - SC | G4: REGIONAL MANAUS | H4: Divisao Iranduba - AM | I4: REGIONAL LITORAL NORTE - SP | J4: Divisão Caraguatatuba Norte - SP | K4: REGIONAL BRAGANÇA | L4: Divisão Atibaia Centro - SP | M4: REGIONAL PRESIDENTE PRUDENTE | N4: Divisão Dracena - SP | O4: REGIONAL SP3 - LESTE | P4: Divisão Extremo Leste - SP3 | Q4: REGIONAL BRASILIA I - DF | R4: Divisão Brasília - DF | S4: REGIONAL OSASCO 1 - SP | T4: Divisão Osasco 1 Centro - SP
A5: REGIONAL RIO DE JANEIRO - RJ1 | B5: Divisão Penha - RJ1 (Antiga X-Leste) | C5: REGIONAL NORDESTE I | D5: Divisão Monsenhor Tabosa - CE | E5: REGIONAL FLORIANOPOLIS | F5: Divisão Florianopolis - SC | G5: REGIONAL MANAUS | H5: Divisão Itacoatiara - AM | I5: REGIONAL LITORAL NORTE - SP | J5: Divisão Caraguatatuba Sul - SP | K5: REGIONAL BRAGANÇA | L5: Divisão Bragança Paulista Centro - SP | M5: REGIONAL PRESIDENTE PRUDENTE | N5: Divisao Presidente Prudente - SP | O5: REGIONAL SP3 - LESTE | P5: Divisão Extremo Oeste - SP3 | Q5: REGIONAL BRASILIA I - DF | R5: Divisão Jardim Botânico - DF | S5: REGIONAL OSASCO 1 - SP | T5: Divisão Osasco 1 Extremo Oeste - SP
A6: REGIONAL RIO DE JANEIRO - RJ1 | B6: Divisão Ilha do Governador - RJ1 | C6: REGIONAL NORDESTE I | D6: Divisão Teresina - PI | E6: REGIONAL FLORIANOPOLIS | F6: Divisão Passo de Torres - SC | G6: REGIONAL MANAUS | H6: Divisão Itapiranga - AM | I6: REGIONAL LITORAL NORTE - SP | J6: Divisão Ilhabela - SP | K6: REGIONAL BRAGANÇA | L6: Divisão Bragança Paulista Norte - SP | M6: REGIONAL PRESIDENTE PRUDENTE | N6: Divisao Presidente Venceslau - SP | O6: REGIONAL SP3 - LESTE | P6: Divisão Extremo Sul - SP3 | Q6: REGIONAL BRASILIA I - DF | R6: Divisão Riacho Fundo - DF | S6: REGIONAL OSASCO 1 - SP | T6: Divisão Osasco 1 Extremo Sul - SP
A7: REGIONAL RIO DE JANEIRO - RJ1 | B7: Divisão Bonsucesso - RJ1 (Antiga Leste) | C7: REGIONAL NORDESTE I | D7: Divisão Tianguá - CE | E7: REGIONAL FLORIANOPOLIS | F7: Divisão Tijucas - SC | G7: REGIONAL MANAUS | H7: Divisao Manaus Centro - AM | I7: REGIONAL LITORAL NORTE - SP | J7: Divisão São Sebastião Norte 1 - SP | K7: REGIONAL BRAGANÇA | L7: Divisao Bragança Paulista Sul - SP | M7: REGIONAL PRESIDENTE PRUDENTE | N7: Divisao Tupi Paulista - SP | O7: REGIONAL SP3 - LESTE | P7: Divisão Leste - SP3 | Q7: REGIONAL BRASILIA I - DF | R7: Divisão São Sebastião - Df | S7: REGIONAL OSASCO 1 - SP | T7: Divisão Osasco 1 Leste - SP
A8: REGIONAL RIO DE JANEIRO - RJ1 | B8: Divisão Tijuca - RJ1 (Antiga Sul) | C8: REGIONAL NORDESTE I | D8: Divisão Parnaíba - PI | E8: REGIONAL FLORIANOPOLIS | F8: Divisão Tubarão - SC | G8: REGIONAL MANAUS | H8: Divisao Manaus Leste - AM | I8: REGIONAL LITORAL NORTE - SP | J8: Divisão Ubatuba - SP | K8: REGIONAL BRAGANÇA | L8: Divisão Morungaba - SP | M8: REGIONAL PRESIDENTE PRUDENTE | N8: Divisao Piraposinho- SP | O8: REGIONAL SP3 - LESTE | P8: Divisão Norte - SP3 | Q8: REGIONAL BRASILIA I - DF | R8: Divisão Vicente Pires - DF
A9: REGIONAL RIO DE JANEIRO - RJ1 | B9: Divisão Copacabana - RJ1 (Antiga Zona Sul) | C9: REGIONAL NORDESTE I | D9: Divisão Sobral - CE | E9: REGIONAL FLORIANOPOLIS | F9: Divisão São José - SC | G9: REGIONAL MANAUS | H9: Divisao Manaus Norte - AM | I9: REGIONAL LITORAL NORTE - SP | J9: Divisão São Sebastião Sul - SP | K9: REGIONAL BRAGANÇA | L9: Divisão Pinhalzinho - SP | M9: REGIONAL PRESIDENTE PRUDENTE | N9: Divisao Osvaldo Cruz - SP (Antiga Div. Bastos) | O9: REGIONAL SP3 - LESTE | P9: Divisão Oeste - SP3 | Q9: REGIONAL BRASILIA I - DF | R9: Divisão Guará - DF | S9: REGIONAL OSASCO 2 - SP
A10: REGIONAL RIO DE JANEIRO - RJ1 | B10: Divisão Méier - RJ1 | C10: REGIONAL NORDESTE I | D10: Divisão Jijoca - CE | E10: REGIONAL FLORIANOPOLIS | F10: Divisão Pachoça - SC | G10: REGIONAL MANAUS | H10: Divisao Manaus Sul - AM | I10: REGIONAL LITORAL NORTE - SP | J10: Divisão Caraguatatuba Centro - SP | K10: REGIONAL BRAGANÇA | L10: Divisão Piracaia - SP | M10: REGIONAL PRESIDENTE PRUDENTE | N10: Divisão Junqueirópolis - SP | O10: REGIONAL SP3 - LESTE | P10: Divisão Sul - SP3 | Q10: REGIONAL BRASILIA I - DF | R10: Divisão Taguatinga - DF | S10: REGIONAL OSASCO 2 - SP | T10: Divisão Osasco 2 Centro Velho - SP
A11: REGIONAL RIO DE JANEIRO - RJ1 | B11: Divisão Maracanã - RJ1 | G11: REGIONAL MANAUS | H11: Divisao Manaus Oeste - AM | I11: REGIONAL LITORAL NORTE - SP | J11: Divisão São Sebastião Centro - SP | K11: REGIONAL BRAGANÇA | L11: Divisão Nazaré Paulista - SP | M11: REGIONAL PRESIDENTE PRUDENTE | N11: Divisão Martinópolis - SP | O11: REGIONAL SP3 - LESTE | P11: Divisão Extremo Norte - SP3 | S11: REGIONAL OSASCO 2 - SP | T11: Divisão Osasco 2 Norte - SP
A12: REGIONAL RIO DE JANEIRO - RJ1 | B12: Divisão Suburbana - RJ1 | C12: REGIONAL NORDESTE II | E12: REGIONAL VALE DO ITAJAÍ - SC | G12: REGIONAL MANAUS | H12: Divisão Presidente Figueiredo - AM | I12: REGIONAL LITORAL NORTE - SP | J12: Divisão São Sebastião Norte 2 - SP | K12: REGIONAL BRAGANÇA | L12: Divisão Pedra Bela - SP | M12: REGIONAL PRESIDENTE PRUDENTE | N12: Divisão Presidente Epitácio - SP | O12: REGIONAL SP3 - LESTE | P12: Divisão Centro - SP3 | Q12: REGIONAL BRASÍLIA II - DF | S12: REGIONAL OSASCO 2 - SP | T12: Divisão Osasco 2 Oeste - SP
A13: REGIONAL RIO DE JANEIRO - RJ1 | B13: Divisão Cachambi - RJ1 | C13: REGIONAL NORDESTE II | D13: Divisão Eusebio - CE | E13: REGIONAL VALE DO ITAJAÍ - SC | F13: Divisão Barra Velha - SC | G13: REGIONAL MANAUS | H13: Divisão Manaus Sudeste - AM | K13: REGIONAL BRAGANÇA | L13: Divisão Joanópolis - SP | Q13: REGIONAL BRASÍLIA II - DF | R13: Divisão Cidade Ocidental - GO | S13: REGIONAL OSASCO 2 - SP | T13: Divisão Osasco 2 Extremo Leste - SP (Antiga Leste)
A14: REGIONAL RIO DE JANEIRO - RJ1 | B14: Divisão Galeão - RJ1 | C14: REGIONAL NORDESTE II | D14: Divisão Fortaleza Centro - CE | E14: REGIONAL VALE DO ITAJAÍ - SC | F14: Divisao Itajaí - SC | G14: REGIONAL MANAUS | H14: Divisão Manacapuru - AM | I14: REGIONAL VALE DO PARAÍBA I - SP | K14: REGIONAL BRAGANÇA | L14: Divisao Bragança Paulista Leste - SP | M14: REGIONAL SÃO JOSÉ DO RIO PRETO | O14: REGIONAL SP5 | Q14: REGIONAL BRASÍLIA II - DF | R14: Divisão Jardim Ingá - GO
A15: REGIONAL RIO DE JANEIRO - RJ1 | B15: Divisão Leblon - RJ1 | C15: REGIONAL NORDESTE II | D15: Divisão Fortaleza Leste - CE | E15: REGIONAL VALE DO ITAJAÍ - SC | F15: Divisão Navegantes - SC | I15: REGIONAL VALE DO PARAÍBA I - SP | J15: Divisão Caçapava - SP | K15: REGIONAL BRAGANÇA | L15: Divisão Atibaia Sul - SP | M15: REGIONAL SÃO JOSÉ DO RIO PRETO | N15: Divisão Barretos - SP | O15: REGIONAL SP5 | P15: Divisão Extremo Leste - SP5 | Q15: REGIONAL BRASÍLIA II - DF | R15: Divisão Luziânia - GO | S15: REGIONAL OSASCO 3 - SP
A16: REGIONAL RIO DE JANEIRO - RJ1 | B16: Divisão Ribeira - RJ1 | C16: REGIONAL NORDESTE II | D16: Divisão Fortaleza Oeste - CE | E16: REGIONAL VALE DO ITAJAÍ - SC | F16: Divisão Penha - SC | G16: REGIONAL RORAIMA | I16: REGIONAL VALE DO PARAÍBA I - SP | J16: Divisão São José dos Campos Centro - SP | K16: REGIONAL BRAGANÇA | L16: Divisão Bom Jesus dos Perdões - SP | M16: REGIONAL SÃO JOSÉ DO RIO PRETO | N16: Divisão Mirassol - SP | O16: REGIONAL SP5 | P16: Divisão Extremo Norte - SP5 | Q16: REGIONAL BRASÍLIA II - DF | R16: Divisão Novo Gama - GO | S16: REGIONAL OSASCO 3 - SP | T16: Divisão Osasco 3 Centro - SP
A17: REGIONAL RIO DE JANEIRO - RJ1 | B17: Divisão Imperial - RJ1 | C17: REGIONAL NORDESTE II | D17: Divisão Litoral Leste - CE | E17: REGIONAL VALE DO ITAJAÍ - SC | F17: Divisao Itajaí Oeste - SC | G17: REGIONAL BOA VISTA | H17: Divisão Boa Vista Centro - RR | I17: REGIONAL VALE DO PARAÍBA I - SP | J17: Divisão São José dos Campos Leste - SP | K17: REGIONAL BRAGANÇA | L17: Divisão Tuiuti - SP | M17: REGIONAL SÃO JOSÉ DO RIO PRETO | N17: Divisao Olimpia - SP | O17: REGIONAL SP5 | P17: Divisão Extremo Oeste 1 - SP5 | Q17: REGIONAL BRASÍLIA II - DF | R17: Divisão Paracatu - MG | S17: REGIONAL OSASCO 3 - SP | T17: Divisão Osasco 3 Oeste - SP
C18: REGIONAL NORDESTE II | D18: Divisão Maracanaú - CE | E18: REGIONAL LITORAL NORTE - SC | F18: Divisão Balneário Piçarras - SC | G18: REGIONAL BOA VISTA | H18: Divisão Boa Vista Leste - RR | I18: REGIONAL VALE DO PARAÍBA I - SP | J18: Divisão São José dos Campos Norte - SP | M18: REGIONAL SÃO JOSÉ DO RIO PRETO | N18: Divisao São José do Rio Preto - SP | O18: REGIONAL SP5 | P18: Divisão Extremo Sul - SP5 | Q18: REGIONAL BRASÍLIA II - DF | R18: Divisão Valparaiso - GO | S18: REGIONAL OSASCO 3 - SP | T18: Divisão Osasco 3 Extremo Norte - SP
A19: REGIONAL RIO DE JANEIRO - RJ2 | C19: REGIONAL NORDESTE II | D19: Divisão Pacajus - CE | E19: REGIONAL LITORAL NORTE - SC | F19: Divisao Ilhota - SC | G19: REGIONAL BOA VISTA | H19: Divisão Boa Vista Norte - RR | I19: REGIONAL VALE DO PARAÍBA I - SP | J19: Divisão São José dos Campos Oeste - SP | K19: REGIONAL MOGIANA - SP | M19: REGIONAL SÃO JOSÉ DO RIO PRETO | N19: Divisão Fronteira - MG | O19: REGIONAL SP5 | P19: Divisão Norte - SP5 | Q19: REGIONAL BRASÍLIA II - DF | R19: Divisão Jardim ABC - GO | S19: REGIONAL OSASCO 3 - SP | T19: Divisão Osasco 3 Sul - SP
A20: REGIONAL RIO DE JANEIRO - RJ2 | B20: Divisão Rio do A - RJ2 (Antiga Centro Oeste) | C20: REGIONAL NORDESTE II | D20: Divisão Vale do Jaguaribe - CE | E20: REGIONAL LITORAL NORTE - SC | F20: Divisão Presidente Getúlio - SC | G20: REGIONAL BOA VISTA | H20: Divisão Boa Vista Oeste - RR | I20: REGIONAL VALE DO PARAÍBA I - SP | J20: Divisão São José dos Campos Sul - SP | K20: REGIONAL MOGIANA - SP | L20: Divisão do Pinhal - SP | M20: REGIONAL SÃO JOSÉ DO RIO PRETO | N20: Divisão São José do Rio Preto Norte - SP | O20: REGIONAL SP5 | P20: Divisão Oeste - SP5 | Q20: REGIONAL BRASÍLIA II - DF | R20: Divisão Cristalina - GO | S20: REGIONAL OSASCO 3 - SP | T20: Divisão Osasco 3 Norte - SP
A21: REGIONAL RIO DE JANEIRO - RJ2 | B21: Divisão Medanha - RJ2 (Antiga X-Oeste) | C21: REGIONAL NORDESTE II | D21: Divisão Cariri - CE | G21: REGIONAL BOA VISTA | H21: Divisão Boa Vista Sul - RR | I21: REGIONAL VALE DO PARAÍBA I - SP | J21: Divisão SJC Extremo Norte - SP | K21: REGIONAL MOGIANA - SP | L21: Divisão Itapira - SP | M21: REGIONAL SÃO JOSÉ DO RIO PRETO | N21: Divisão São José do Rio Preto Leste - SP | O21: REGIONAL SP5 | P21: Divisão Sul - SP5 | S21: REGIONAL OSASCO 3 - SP | T21: Divisão Osasco 3 Extremo Oeste - SP
A22: REGIONAL RIO DE JANEIRO - RJ2 | B22: Divisão Guaratiba - RJ2 (Antiga X-Sul) | C22: REGIONAL NORDESTE II | D22: Divisão Aquiraz - CE | E22: REGIONAL PLANALTO NORTE - SC | G22: REGIONAL BOA VISTA | H22: Divisão Rorainópolis - RR | I22: REGIONAL VALE DO PARAÍBA I - SP | J22: Divisão SJC Extremo Sul - SP | K22: REGIONAL MOGIANA - SP | L22: Divisão Jaguariúna - SP | M22: REGIONAL SÃO JOSÉ DO RIO PRETO | N22: Divisão Catanduva - SP | O22: REGIONAL SP5 | P22: Divisão Extremo Oeste 2 - SP5 | Q22: REGIONAL BRASÍLIA III - DF
A23: REGIONAL RIO DE JANEIRO - RJ2 | B23: Divisão Paciência- RJ2 (Antiga Litoral Oeste) | C23: REGIONAL NORDESTE II | D23: Divisão Mauriti - CE | E23: REGIONAL PLANALTO NORTE - SC | F23: Divisão Canoinhas - SC | G23: REGIONAL BOA VISTA | H23: Divisão Rorainópolis II - RR | I23: REGIONAL VALE DO PARAÍBA I - SP | J23: Divisão SJC Extremo Leste - SP | K23: REGIONAL MOGIANA - SP | L23: Divisao Mogi Guaçu - SP | M23: REGIONAL SÃO JOSÉ DO RIO PRETO | N23: Divisão Guaraci - SP | O23: REGIONAL SP5 | P23: Divisão Extremo Leste 2 - SP5 | Q23: REGIONAL BRASÍLIA III - DF | R23: Divisão Águas Lindas - GO | S23: REGIONAL OSASCO 4 - SP
A24: REGIONAL RIO DE JANEIRO - RJ2 | B24: Divisão Rio da Prata - RJ2 (Antiga Norte) | C24: REGIONAL NORDESTE II | D24: Divisão Fortaleza Sul - CE | E24: REGIONAL PLANALTO NORTE - SC | F24: Divisão Guaramirim - SC | I24: REGIONAL VALE DO PARAÍBA I - SP | J24: Divisão Paraibuna - SP | K24: REGIONAL MOGIANA - SP | L24: Divisao Mogi Mirim - SP | M24: REGIONAL SÃO JOSÉ DO RIO PRETO | N24: Divisão Monte Aprazível - SP | Q24: REGIONAL BRASÍLIA III - DF | R24: Divisão Ceilândia - DF | S24: REGIONAL OSASCO 4 - SP | T24: Divisão Osasco 4 Extremo Leste - SP
A25: REGIONAL RIO DE JANEIRO - RJ2 | B25: Divisão Bangú - RJ2 | C25: REGIONAL NORDESTE II | D25: Divisão Juazeiro - CE | E25: REGIONAL PLANALTO NORTE - SC | F25: Divisão Jaraguá do Sul - SC | G25: REGIONAL ACRE | I25: REGIONAL VALE DO PARAÍBA I - SP | J25: Divisão Caçapava II - SP | K25: REGIONAL MOGIANA - SP | L25: Divisao Pedreira - SP | M25: REGIONAL SÃO JOSÉ DO RIO PRETO | N25: Divisão José Bonifácio - SP | O25: REGIONAL SP10 | Q25: REGIONAL BRASÍLIA III - DF | R25: Divisão Gama - DF | S25: REGIONAL OSASCO 4 - SP | T25: Divisão Osasco 4 Sul - SP
A26: REGIONAL RIO DE JANEIRO - RJ2 | B26: Divisão Mato Alto - RJ2 | C26: REGIONAL NORDESTE II | D26: Divisão Crato - CE | E26: REGIONAL PLANALTO NORTE - SC | F26: Divisao Rio Negrinho - SC | G26: REGIONAL ACRE | H26: Divisão Boca do Acre - AM | K26: REGIONAL MOGIANA - SP | L26: Divisão Gerbi - SP | M26: REGIONAL SÃO JOSÉ DO RIO PRETO | N26: Divisão Icém - SP | O26: REGIONAL SP10 | P26: Divisão Norte - SP10 | Q26: REGIONAL BRASÍLIA III - DF | R26: Divisão Recanto das Emas - DF | S26: REGIONAL OSASCO 4 - SP | T26: Divisão Osasco 4 Oeste - SP (Antiga X-Leste)
A27: REGIONAL RIO DE JANEIRO - RJ2 | B27: Divisão Inhoaíba - RJ2 | C27: REGIONAL NORDESTE II | D27: Divisão Campina Grande do Sul - PR | E27: REGIONAL PLANALTO NORTE - SC | F27: Divisão São Bento do Sul - SC | G27: REGIONAL ACRE | H27: Divisão Rio Branco - AC | I27: REGIONAL VALE DO PARAÍBA II - SP | K27: REGIONAL MOGIANA - SP | L27: Divisão Itapira Sul - SP | M27: REGIONAL SÃO JOSÉ DO RIO PRETO | N27: Divisão São José do Rio Preto Centro - SP | O27: REGIONAL SP10 | P27: Divisão Sul - SP10 | Q27: REGIONAL BRASÍLIA III - DF | R27: Divisão Samambaia - DF | S27: REGIONAL OSASCO 4 - SP | T27: Divisão Osasco 4 Norte - SP
A28: REGIONAL RIO DE JANEIRO - RJ2 | B28: Divisão Padre Miguel - RJ2 | E28: REGIONAL PLANALTO NORTE - SC | F28: Divisão Schroeder - SC | G28: REGIONAL ACRE | H28: Divisão Cruzeiro do Sul - AC | I28: REGIONAL VALE DO PARAÍBA II - SP | J28: Divisão Guaratinguetá - SP | M28: REGIONAL SÃO JOSÉ DO RIO PRETO | N28: Divisão São José do Rio Preto Sul - SP | O28: REGIONAL SP10 | P28: Divisão Leste - SP10 | Q28: REGIONAL BRASÍLIA III - DF | R28: Divisão Santa Maria - DF
A29: REGIONAL RIO DE JANEIRO - RJ2 | B29: Divisão Campo Grande - RJ2 | C29: REGIONAL NORDESTE III | E29: REGIONAL PLANALTO NORTE - SC | F29: Divisão Campo Alegre - SC | I29: REGIONAL VALE DO PARAÍBA II - SP | J29: Divisão Pindamonhangaba - SP | K29: REGIONAL SÃO JOÃO DA BOA VISTA - SP | M29: REGIONAL SÃO JOSÉ DO RIO PRETO | N29: Divisão Cardoso - SP | O29: REGIONAL SP10 | P29: Divisão Oeste - SP10 | S29: REGIONAL OSASCO 5 - SP
A30: REGIONAL RIO DE JANEIRO - RJ2 | B30: Divisão Barra de Guaratiba - RJ2 | C30: REGIONAL NORDESTE III | D30: Divisão Mossoró - RN | E30: REGIONAL PLANALTO NORTE - SC | F30: Divisão Mafra - SC | I30: REGIONAL VALE DO PARAÍBA II - SP | J30: Divisão Taubaté - SP | K30: REGIONAL SÃO JOÃO DA BOA VISTA - SP | L30: Divisão Poços de Caldas - MG | M30: REGIONAL SÃO JOSÉ DO RIO PRETO | N30: Divisão São José do Rio Preto Sul - SP | O30: REGIONAL SP10 | P30: Divisão Extremo Norte - SP10 | Q30: REGIONAL BRASÍLIA IV- DF | S30: REGIONAL OSASCO 5 - SP | T30: Divisão Osasco 5 Extremo Oeste - SP
A31: REGIONAL RIO DE JANEIRO - RJ2 | B31: Divisão Magalhães Bastos - RJ2 | C31: REGIONAL NORDESTE III | D31: Divisão Natal - RN | E31: REGIONAL PLANALTO NORTE - SC | F31: Divisão Corupá - SC | I31: REGIONAL VALE DO PARAÍBA II - SP | J31: Divisão Tremembé - SP | K31: REGIONAL SÃO JOÃO DA BOA VISTA - SP | L31: Divisao São Joao da Boa Vista - SP | M31: REGIONAL SÃO JOSÉ DO RIO PRETO | N31: Divisão Bady Bassit - SP | O31: REGIONAL SP10 | P31: Divisão Extremo Sul - SP10 | Q31: REGIONAL BRASÍLIA IV - DF | R31: Divisão Formosa - GO | S31: REGIONAL OSASCO 5 - SP | T31: Divisão Osasco 5 Leste - SP (Antiga Oeste)
A32: REGIONAL RIO DE JANEIRO - RJ2 | B32: Divisão Campinho - RJ2 | C32: REGIONAL NORDESTE III | D32: Divisão Parnamirim - RN | E32: REGIONAL PLANALTO NORTE - SC | F32: Divisão Porto União - SC | I32: REGIONAL VALE DO PARAÍBA II - SP | J32: Divisão Redenção da Serra - SP | K32: REGIONAL SÃO JOÃO DA BOA VISTA - SP | L32: Divisão Vargem Grande do Sul - SP | O32: REGIONAL SP10 | P32: Divisão Extremo Oeste - SP10 | Q32: REGIONAL BRASÍLIA IV - DF | R32: Divisão Paranoá - DF | S32: REGIONAL OSASCO 5 - SP | T32: Divisão Osasco 5 Centro - SP (Antiga X-Oeste)
C33: REGIONAL NORDESTE III | D33: Divisão Ceará-Mirim - RN | E33: REGIONAL PLANALTO NORTE - SC | F33: Divisão Rio Negrinho Norte - SC | I33: REGIONAL VALE DO PARAÍBA II - SP | J33: Divisão Moreira César - SP | K33: REGIONAL SÃO JOÃO DA BOA VISTA - SP | L33: Divisão Águas da Prata - SP | M33: REGIONAL ANDRADINA | O33: REGIONAL SP10 | P33: Divisão Extremo Leste - SP10 | Q33: REGIONAL BRASÍLIA IV - DF | R33: Divisão Planaltina - GO
A34: REGIONAL RIO DE JANEIRO - RJ3 | C34: REGIONAL NORDESTE III | D34: Divisão Seridó - RN | I34: REGIONAL VALE DO PARAÍBA II - SP | J34: Divisão Santo Antônio do Pinhal - SP | K34: REGIONAL SÃO JOÃO DA BOA VISTA - SP | L34: Divisao Aguaí - SP | M34: REGIONAL ANDRADINA | N34: Divisão Andradina - SP | O34: REGIONAL SP10 | P34: Divisão Centro - SP10 | Q34: REGIONAL BRASÍLIA IV - DF | R34: Divisão Planaltina - DF
A35: REGIONAL RIO DE JANEIRO - RJ3 | B35: Divisão Vila Valqueire - RJ3 (Antiga X-Norte) | C35: REGIONAL NORDESTE III | D35: Divisão Campina Grande - PB | E35: REGIONAL LITORAL SUL - SC | I35: REGIONAL VALE DO PARAÍBA II - SP | J35: Divisão Pindamonhangaba II - SP | M35: REGIONAL ANDRADINA | N35: Divisão Ilha Solteira - SP | Q35: REGIONAL BRASÍLIA IV - DF | R35: Divisão Sobradinho - DF
A36: REGIONAL RIO DE JANEIRO - RJ3 | B36: Divisão Inhaúma - RJ3 (Antiga Norte) | C36: REGIONAL NORDESTE III | D36: Divisão João Pessoa Norte - PB | E36: REGIONAL LITORAL SUL - SC | F36: Divisão Itapema - SC | I36: REGIONAL VALE DO PARAÍBA II - SP | J36: Divisão Pindamonhangaba III - SP | K36: REGIONAL CIRCUITO DAS ÁGUAS - SP | M36: REGIONAL ANDRADINA | N36: Divisão Castilho - SP | O36: REGIONAL SP13 | Q36: REGIONAL BRASÍLIA IV - DF | R36: Divisão Unaí - MG
A37: REGIONAL RIO DE JANEIRO - RJ3 | B37: Divisão Madureira -RJ3 | E37: REGIONAL LITORAL SUL - SC | F37: Divisão Bombinhas - SC | I37: REGIONAL VALE DO PARAÍBA II - SP | J37: Divisão Taubaté II - SP | K37: REGIONAL CIRCUITO DAS ÁGUAS - SP | L37: Divisão Socorro - SP | M37: REGIONAL ANDRADINA | N37: Divisão Pereira Barreto - SP | O37: REGIONAL SP13 | P37: Divisão Leste - SP13
A38: REGIONAL RIO DE JANEIRO - RJ3 | B38: Divisão Irajá - RJ3 | C38: REGIONAL NORDESTE VI | E38: REGIONAL LITORAL SUL - SC | F38: Divisão Porto Belo - SC | I38: REGIONAL VALE DO PARAÍBA II - SP | J38: Divisão Campos do Jordão - SP | K38: REGIONAL CIRCUITO DAS ÁGUAS - SP | L38: Divisao Águas de Lindóia - SP | M38: REGIONAL ANDRADINA | N38: Divisão Murutinga do Sul - SP | O38: REGIONAL SP13 | P38: Divisão Oeste - SP13 | Q38: REGIONAL TOCANTINS
A39: REGIONAL RIO DE JANEIRO - RJ3 | B39: Divisão Sulacap - RJ3 | C39: REGIONAL NORDESTE VI | D39: Divisão Barreirinhas - MA | K39: REGIONAL CIRCUITO DAS ÁGUAS - SP | L39: Divisão Lindóia - SP | M39: REGIONAL ANDRADINA | N39: Divisão Mirandópolis - SP | O39: REGIONAL SP13 | P39: Divisão Norte - SP13 | Q39: REGIONAL TOCANTINS | R39: Divisão Araguaína - TO
A40: REGIONAL RIO DE JANEIRO - RJ3 | B40: Divisão Penha Circular - RJ3 | C40: REGIONAL NORDESTE VI | D40: Divisão Paço do Lumiar - MA | E40: REGIONAL LITORAL NORTE - SC | I40: REGIONAL VALE DO PARAÍBA III - SP | K40: REGIONAL CIRCUITO DAS ÁGUAS - SP | L40: Divisão Amparo - SP | O40: REGIONAL SP13 | P40: Divisão Centro - SP13 | Q40: REGIONAL TOCANTINS | R40: Divisão Gurupi Sul - TO
...

Sheet CMD I
A1: VOLTAR
A2: Comando Regional I | E2: *CMD REGIONAL I*
A3: REGIONAL RIO DE JANEIRO - RJ1 | E3: =CAPA!B6 -> Representante: Alex
A4: REGIONAL RIO DE JANEIRO - RJ1 | B4: Divisão Centro - RJ1 | E4: =CAPA!B7 -> Cmd Brasil: Borges
A5: REGIONAL RIO DE JANEIRO - RJ1 | B5: Divisão Penha - RJ1 (Antiga X-Leste) | E5: =CAPA!B8 -> Disciplina: Machete
A6: REGIONAL RIO DE JANEIRO - RJ1 | B6: Divisão Ilha do Governador - RJ1 | E6: =CAPA!B9 -> Inteligência: Daniel
A7: REGIONAL RIO DE JANEIRO - RJ1 | B7: Divisão Bonsucesso - RJ1 (Antiga Leste) | E7: =CAPA!B10 -> Adm Cmd:
A8: REGIONAL RIO DE JANEIRO - RJ1 | B8: Divisão Tijuca - RJ1 (Antiga Sul) | E8: =CAPA!B11 -> Expansão: Tibão / Marmita
A9: REGIONAL RIO DE JANEIRO - RJ1 | B9: Divisão Copacabana - RJ1 (Antiga Zona Sul) | E9: =CAPA!B12 -> Comunicação: Barney
A10: REGIONAL RIO DE JANEIRO - RJ1 | B10: Divisão Méier - RJ1 | E10: =CAPA!B13 -> Operacional: Eric
A11: REGIONAL RIO DE JANEIRO - RJ1 | B11: Divisão Maracanã - RJ1 | E11: =CAPA!B14 -> Armas: Zimermam
A12: REGIONAL RIO DE JANEIRO - RJ1 | B12: Divisão Suburbana - RJ1
A13: REGIONAL RIO DE JANEIRO - RJ1 | B13: Divisão Cachambi - RJ1
A14: REGIONAL RIO DE JANEIRO - RJ1 | B14: Divisão Galeão - RJ1
A15: REGIONAL RIO DE JANEIRO - RJ1 | B15: Divisão Leblon - RJ1
A16: REGIONAL RIO DE JANEIRO - RJ1 | B16: Divisão Ribeira - RJ1
A17: REGIONAL RIO DE JANEIRO - RJ1 | B17: Divisão Imperial - RJ1
A19: REGIONAL RIO DE JANEIRO - RJ2
A20: REGIONAL RIO DE JANEIRO - RJ2 | B20: Divisão Rio do A - RJ2 (Antiga Centro Oeste)
A21: REGIONAL RIO DE JANEIRO - RJ2 | B21: Divisão Medanha - RJ2 (Antiga X-Oeste)
A22: REGIONAL RIO DE JANEIRO - RJ2 | B22: Divisão Guaratiba - RJ2 (Antiga X-Sul)
A23: REGIONAL RIO DE JANEIRO - RJ2 | B23: Divisão Paciência- RJ2 (Antiga Litoral Oeste)
A24: REGIONAL RIO DE JANEIRO - RJ2 | B24: Divisão Rio da Prata - RJ2 (Antiga Norte)
A25: REGIONAL RIO DE JANEIRO - RJ2 | B25: Divisão Bangú - RJ2
A26: REGIONAL RIO DE JANEIRO - RJ2 | B26: Divisão Mato Alto - RJ2
A27: REGIONAL RIO DE JANEIRO - RJ2 | B27: Divisão Inhoaíba - RJ2
A28: REGIONAL RIO DE JANEIRO - RJ2 | B28: Divisão Padre Miguel - RJ2
A29: REGIONAL RIO DE JANEIRO - RJ2 | B29: Divisão Campo Grande - RJ2
A30: REGIONAL RIO DE JANEIRO - RJ2 | B30: Divisão Barra de Guaratiba - RJ2
A31: REGIONAL RIO DE JANEIRO - RJ2 | B31: Divisão Magalhães Bastos - RJ2
A32: REGIONAL RIO DE JANEIRO - RJ2 | B32: Divisão Campinho - RJ2
A34: REGIONAL RIO DE JANEIRO - RJ3
A35: REGIONAL RIO DE JANEIRO - RJ3 | B35: Divisão Vila Valqueire - RJ3 (Antiga X-Norte)
A36: REGIONAL RIO DE JANEIRO - RJ3 | B36: Divisão Inhaúma - RJ3 (Antiga Norte)
A37: REGIONAL RIO DE JANEIRO - RJ3 | B37: Divisão Madureira -RJ3
A38: REGIONAL RIO DE JANEIRO - RJ3 | B38: Divisão Irajá - RJ3
A39: REGIONAL RIO DE JANEIRO - RJ3 | B39: Divisão Sulacap - RJ3
A40: REGIONAL RIO DE JANEIRO - RJ3 | B40: Divisão Penha Circular - RJ3
A41: REGIONAL RIO DE JANEIRO - RJ3 | B41: Divisão Piedade - RJ3
A42: REGIONAL RIO DE JANEIRO - RJ3 | B42: Divisão Pavuna - RJ3
...

Sheet CMD II
A1: VOLTAR
A2: Comando Regional II | D2: *CMD REGIONAL II*
A3: REGIONAL NORDESTE I | D3: =CAPA!C6 -> Mundial: Naruê
A4: REGIONAL NORDESTE I | B4: Divisão Ibiapina - CE | D4: =CAPA!C7 -> Cmd Brasil: Bardo
A5: REGIONAL NORDESTE I | B5: Divisão Monsenhor Tabosa - CE | D5: =CAPA!C8 -> Disciplina: Ching
A6: REGIONAL NORDESTE I | B6: Divisão Teresina - PI | D6: =CAPA!C9 -> Inteligência: Custódio
A7: REGIONAL NORDESTE I | B7: Divisão Tianguá - CE | D7: =CAPA!C10 -> Adm Cmd:
A8: REGIONAL NORDESTE I | B8: Divisão Parnaíba - PI | D8: =CAPA!C11 -> Expansão: Tibão / Diego
A9: REGIONAL NORDESTE I | B9: Divisão Sobral - CE | D9: =CAPA!C12 -> Comunicação: Barney
A10: REGIONAL NORDESTE I | B10: Divisão Jijoca - CE | D10: =CAPA!C13 -> Operacional: Roney / Invictus
D11: =CAPA!C14 -> Armas: Carcará
A12: REGIONAL NORDESTE II
A13: REGIONAL NORDESTE II | B13: Divisão Eusebio - CE
A14: REGIONAL NORDESTE II | B14: Divisão Fortaleza Centro - CE
A15: REGIONAL NORDESTE II | B15: Divisão Fortaleza Leste - CE
A16: REGIONAL NORDESTE II | B16: Divisão Fortaleza Oeste - CE
A17: REGIONAL NORDESTE II | B17: Divisão Litoral Leste - CE
A18: REGIONAL NORDESTE II | B18: Divisão Maracanaú - CE
A19: REGIONAL NORDESTE II | B19: Divisão Pacajus - CE
A20: REGIONAL NORDESTE II | B20: Divisão Vale do Jaguaribe - CE
A21: REGIONAL NORDESTE II | B21: Divisão Cariri - CE
A22: REGIONAL NORDESTE II | B22: Divisão Aquiraz - CE
A23: REGIONAL NORDESTE II | B23: Divisão Mauriti - CE
A24: REGIONAL NORDESTE II | B24: Divisão Fortaleza Sul - CE
... A27: REGIONAL NORDESTE II | B27: Divisão Campina Grande do Sul - PR
A29: REGIONAL NORDESTE III
A30: REGIONAL NORDESTE III | B30: Divisão Mossoró - RN
A31: REGIONAL NORDESTE III | B31: Divisão Natal - RN
A32: REGIONAL NORDESTE III | B32: Divisão Parnamirim - RN
A33: REGIONAL NORDESTE III | B33: Divisão Ceará-Mirim - RN
A34: REGIONAL NORDESTE III | B34: Divisão Seridó - RN
A35: REGIONAL NORDESTE III | B35: Divisão Campina Grande - PB
A36: REGIONAL NORDESTE III | B36: Divisão João Pessoa Norte - PB
A38: REGIONAL NORDESTE VI
A39: REGIONAL NORDESTE VI | B39: Divisão Barreirinhas - MA
A40: REGIONAL NORDESTE VI | B40: Divisão Paço do Lumiar - MA
A41: REGIONAL NORDESTE VI | B41: Divisão Santa Inês - MA
A42: REGIONAL NORDESTE VI | B42: Divisão São José de Ribamar - MA
A43: REGIONAL NORDESTE VI | B43: Divisão São Luis - MA
A44: REGIONAL NORDESTE VI | B44: Divisão Raposa - MA
...

Sheet CMD III
A1: VOLTAR
A2: Comando Regional III | D2: *CMD REGIONAL III*
A3: REGIONAL FLORIANOPOLIS | D3: =CAPA!D6 -> Representante: Véio
A4: REGIONAL FLORIANOPOLIS | B4: Divisão Criciúma - SC | D4: =CAPA!D7 -> Cmd Brasil: Bad
A5: REGIONAL FLORIANOPOLIS | B5: Divisão Florianopolis - SC | D5: =CAPA!D8 -> Disciplina: Cidão
A6: REGIONAL FLORIANOPOLIS | B6: Divisão Passo de Torres - SC | D6: =CAPA!D9 -> Inteligência: Fico
A7: REGIONAL FLORIANOPOLIS | B7: Divisão Tijucas - SC | D7: =CAPA!D10 -> Adm Cmd: Jonnhy
A8: REGIONAL FLORIANOPOLIS | B8: Divisão Tubarão - SC | D8: =CAPA!D11 -> Expansão: Tibão / Edinho
A9: REGIONAL FLORIANOPOLIS | B9: Divisão São José - SC | D9: =CAPA!D12 -> Comunicação: Cruvinel
A10: REGIONAL FLORIANOPOLIS | B10: Divisão Pachoça - SC | D10: =CAPA!D13 -> Operacional: Godoy / Machado
D11: =CAPA!D14 -> Armas: Gomes
A12: REGIONAL VALE DO ITAJAÍ - SC
A13: REGIONAL VALE DO ITAJAÍ - SC | B13: Divisão Barra Velha - SC
A14: REGIONAL VALE DO ITAJAÍ - SC | B14: Divisao Itajaí - SC
A15: REGIONAL VALE DO ITAJAÍ - SC | B15: Divisão Navegantes - SC
A16: REGIONAL VALE DO ITAJAÍ - SC | B16: Divisão Penha - SC
A17: REGIONAL VALE DO ITAJAÍ - SC | B17: Divisao Itajaí Oeste - SC
A18: REGIONAL LITORAL NORTE - SC | B18: Divisão Balneário Piçarras - SC
A19: REGIONAL LITORAL NORTE - SC | B19: Divisao Ilhota - SC
A20: REGIONAL LITORAL NORTE - SC | B20: Divisão Presidente Getúlio - SC
A22: REGIONAL PLANALTO NORTE - SC
A23: REGIONAL PLANALTO NORTE - SC | B23: Divisão Canoinhas - SC
A24: REGIONAL PLANALTO NORTE - SC | B24: Divisão Guaramirim - SC
A25: REGIONAL PLANALTO NORTE - SC | B25: Divisão Jaraguá do Sul - SC
A26: REGIONAL PLANALTO NORTE - SC | B26: Divisao Rio Negrinho - SC
A27: REGIONAL PLANALTO NORTE - SC | B27: Divisão São Bento do Sul - SC
A28: REGIONAL PLANALTO NORTE - SC | B28: Divisão Schroeder - SC
A29: REGIONAL PLANALTO NORTE - SC | B29: Divisão Campo Alegre - SC
A30: REGIONAL PLANALTO NORTE - SC | B30: Divisão Mafra - SC
A31: REGIONAL PLANALTO NORTE - SC | B31: Divisão Corupá - SC
A32: REGIONAL PLANALTO NORTE - SC | B32: Divisão Porto União - SC
A33: REGIONAL PLANALTO NORTE - SC | B33: Divisão Rio Negrinho Norte - SC
A35: REGIONAL LITORAL SUL - SC
A36: REGIONAL LITORAL SUL - SC | B36: Divisão Itapema - SC
A37: REGIONAL LITORAL SUL - SC | B37: Divisão Bombinhas - SC
A38: REGIONAL LITORAL SUL - SC | B38: Divisão Porto Belo - SC
A40: REGIONAL LITORAL NORTE - SC
A41: REGIONAL LITORAL NORTE - SC | B41: Divisão São Francisco do Sul - SC
A42: REGIONAL LITORAL NORTE - SC | B42: Divisão Joinville - SC
A43: REGIONAL LITORAL NORTE - SC | B43: Divisão Joinville Norte - SC
...

Sheet CMD IV
A1: VOLTAR
A2: Comando Regional IV | D2: *CMD REGIONAL IV*
A3: REGIONAL MANAUS | D3: =CAPA!E6 -> Mundial: Diego
A4: REGIONAL MANAUS | B4: Divisao Iranduba - AM | D4: =CAPA!E7 -> Cmd Regional: Marcio
A5: REGIONAL MANAUS | B5: Divisão Itacoatiara - AM | D5: =CAPA!E8 -> Disciplina: Machete
A6: REGIONAL MANAUS | B6: Divisão Itapiranga - AM | D6: =CAPA!E9 -> Inteligência: Custódio
A7: REGIONAL MANAUS | B7: Divisao Manaus Centro - AM | D7: =CAPA!E10 -> Adm Cmd:
A8: REGIONAL MANAUS | B8: Divisao Manaus Leste - AM | D8: =CAPA!E11 -> Expansão: Tibão / Kracoldo
A9: REGIONAL MANAUS | B9: Divisao Manaus Norte - AM | D9: =CAPA!E12 -> Comunicação: Barney
A10: REGIONAL MANAUS | B10: Divisao Manaus Sul - AM | D10: =CAPA!E13 -> Operacional: Ted / Alemão / Mão
A11: REGIONAL MANAUS | B11: Divisao Manaus Oeste - AM | D11: =CAPA!E14 -> Armas: Giordane
A12: REGIONAL MANAUS | B12: Divisão Presidente Figueiredo - AM
A13: REGIONAL MANAUS | B13: Divisão Manaus Sudeste - AM
A14: REGIONAL MANAUS | B14: Divisão Manacapuru - AM
A16: REGIONAL RORAIMA
A17: REGIONAL BOA VISTA | B17: Divisão Boa Vista Centro - RR
A18: REGIONAL BOA VISTA | B18: Divisão Boa Vista Leste - RR
A19: REGIONAL BOA VISTA | B19: Divisão Boa Vista Norte - RR
A20: REGIONAL BOA VISTA | B20: Divisão Boa Vista Oeste - RR
A21: REGIONAL BOA VISTA | B21: Divisão Boa Vista Sul - RR
A22: REGIONAL BOA VISTA | B22: Divisão Rorainópolis - RR
A23: REGIONAL BOA VISTA | B23: Divisão Rorainópolis II - RR
A25: REGIONAL ACRE
A26: REGIONAL ACRE | B26: Divisão Boca do Acre - AM
A27: REGIONAL ACRE | B27: Divisão Rio Branco - AC
A28: REGIONAL ACRE | B28: Divisão Cruzeiro do Sul - AC

Sheet CMD V
A1: VOLTAR
A2: Comando Regional V | D2: *CMD REGIONAL V*
A3: REGIONAL LITORAL NORTE - SP | D3: =CAPA!F6 -> Mundial: Naruê
A4: REGIONAL LITORAL NORTE - SP | B4: Divisão Caraguatatuba Norte - SP | D4: =CAPA!F7 -> Cmd Brasil: Acarlos
A5: REGIONAL LITORAL NORTE - SP | B5: Divisão Caraguatatuba Sul - SP | D5: =CAPA!F8 -> Disciplina: Ching
A6: REGIONAL LITORAL NORTE - SP | B6: Divisão Ilhabela - SP | D6: =CAPA!F9 -> Inteligência: Chaves
A7: REGIONAL LITORAL NORTE - SP | B7: Divisão São Sebastião Norte 1 - SP | D7: =CAPA!F10 -> Adm Cmd: Cabelo
A8: REGIONAL LITORAL NORTE - SP | B8: Divisão Ubatuba - SP | D8: =CAPA!F11 -> Expansão: Tibão / Noslek
A9: REGIONAL LITORAL NORTE - SP | B9: Divisão São Sebastião Sul - SP | D9: =CAPA!F12 -> Comunicação: Chris Jr
A10: REGIONAL LITORAL NORTE - SP | B10: Divisão Caraguatatuba Centro - SP | D10: =CAPA!F13 -> Operacional: Roney / Tozão
A11: REGIONAL LITORAL NORTE - SP | B11: Divisão São Sebastião Centro - SP | D11: =CAPA!F14 -> Armas: Cembra
A12: REGIONAL LITORAL NORTE - SP | B12: Divisão São Sebastião Norte 2 - SP
A14: REGIONAL VALE DO PARAÍBA I - SP
A15: REGIONAL VALE DO PARAÍBA I - SP | B15: Divisão Caçapava - SP
A16: REGIONAL VALE DO PARAÍBA I - SP | B16: Divisão São José dos Campos Centro - SP
A17: REGIONAL VALE DO PARAÍBA I - SP | B17: Divisão São José dos Campos Leste - SP
A18: REGIONAL VALE DO PARAÍBA I - SP | B18: Divisão São José dos Campos Norte - SP
A19: REGIONAL VALE DO PARAÍBA I - SP | B19: Divisão São José dos Campos Oeste - SP
A20: REGIONAL VALE DO PARAÍBA I - SP | B20: Divisão São José dos Campos Sul - SP
A21: REGIONAL VALE DO PARAÍBA I - SP | B21: Divisão SJC Extremo Norte - SP
A22: REGIONAL VALE DO PARAÍBA I - SP | B22: Divisão SJC Extremo Sul - SP
A23: REGIONAL VALE DO PARAÍBA I - SP | B23: Divisão SJC Extremo Leste - SP
A24: REGIONAL VALE DO PARAÍBA I - SP | B24: Divisão Paraibuna - SP
A25: REGIONAL VALE DO PARAÍBA I - SP | B25: Divisão Caçapava II - SP
A27: REGIONAL VALE DO PARAÍBA II - SP
A28: REGIONAL VALE DO PARAÍBA II - SP | B28: Divisão Guaratinguetá - SP
A29: REGIONAL VALE DO PARAÍBA II - SP | B29: Divisão Pindamonhangaba - SP
A30: REGIONAL VALE DO PARAÍBA II - SP | B30: Divisão Taubaté - SP
A31: REGIONAL VALE DO PARAÍBA II - SP | B31: Divisão Tremembé - SP
A32: REGIONAL VALE DO PARAÍBA II - SP | B32: Divisão Redenção da Serra - SP
A33: REGIONAL VALE DO PARAÍBA II - SP | B33: Divisão Moreira César - SP
A34: REGIONAL VALE DO PARAÍBA II - SP | B34: Divisão Santo Antônio do Pinhal - SP
A35: REGIONAL VALE DO PARAÍBA II - SP | B35: Divisão Pindamonhangaba II - SP
A36: REGIONAL VALE DO PARAÍBA II - SP | B36: Divisão Pindamonhangaba III - SP
A37: REGIONAL VALE DO PARAÍBA II - SP | B37: Divisão Taubaté II - SP
A38: REGIONAL VALE DO PARAÍBA II - SP | B38: Divisão Campos do Jordão - SP
A40: REGIONAL VALE DO PARAÍBA III - SP
A41: REGIONAL VALE DO PARAÍBA III - SP | B41: Divisão Jacareí Centro - SP
A42: REGIONAL VALE DO PARAÍBA III - SP | B42: Divisão Jacareí Leste - SP
A43: REGIONAL VALE DO PARAÍBA III - SP | B43: Divisão Jacareí Norte - SP
...

Sheet CMD VI
A1: VOLTAR
A2: Comando Regional VI | D2: *CMD REGIONAL VI*
A3: REGIONAL BRAGANÇA | D3: =CAPA!B16 -> Mundial: Kefir
A4: REGIONAL BRAGANÇA | B4: Divisão Atibaia Centro - SP | D4: =CAPA!B17 -> Cmd Brasil: JJ
A5: REGIONAL BRAGANÇA | B5: Divisão Bragança Paulista Centro - SP | D5: =CAPA!B18 -> Disciplina: K
A6: REGIONAL BRAGANÇA | B6: Divisão Bragança Paulista Norte - SP | D6: =CAPA!B19 -> Inteligência: Dias
A7: REGIONAL BRAGANÇA | B7: Divisao Bragança Paulista Sul - SP | D7: =CAPA!B20 -> Adm Cmd: Brow
A8: REGIONAL BRAGANÇA | B8: Divisão Morungaba - SP | D8: =CAPA!B21 -> Expansão: Tibão / Kracoldo
A9: REGIONAL BRAGANÇA | B9: Divisão Pinhalzinho - SP | D9: =CAPA!B22 -> Comunicação: Barney
A10: REGIONAL BRAGANÇA | B10: Divisão Piracaia - SP | D10: =CAPA!B23 -> Operacional: Ted / Matheus
A11: REGIONAL BRAGANÇA | B11: Divisão Nazaré Paulista - SP | D11: =CAPA!B24 -> Armas: Montesinos
A12: REGIONAL BRAGANÇA | B12: Divisão Pedra Bela - SP
A13: REGIONAL BRAGANÇA | B13: Divisão Joanópolis - SP
A14: REGIONAL BRAGANÇA | B14: Divisao Bragança Paulista Leste - SP
A15: REGIONAL BRAGANÇA | B15: Divisão Atibaia Sul - SP
A16: REGIONAL BRAGANÇA | B16: Divisão Bom Jesus dos Perdões - SP
A17: REGIONAL BRAGANÇA | B17: Divisão Tuiuti - SP
A19: REGIONAL MOGIANA - SP
A20: REGIONAL MOGIANA - SP | B20: Divisão do Pinhal - SP
A21: REGIONAL MOGIANA - SP | B21: Divisão Itapira - SP
A22: REGIONAL MOGIANA - SP | B22: Divisão Jaguariúna - SP
A23: REGIONAL MOGIANA - SP | B23: Divisao Mogi Guaçu - SP
A24: REGIONAL MOGIANA - SP | B24: Divisao Mogi Mirim - SP
A25: REGIONAL MOGIANA - SP | B25: Divisao Pedreira - SP
A26: REGIONAL MOGIANA - SP | B26: Divisão Gerbi - SP
A27: REGIONAL MOGIANA - SP | B27: Divisão Itapira Sul - SP
A29: REGIONAL SÃO JOÃO DA BOA VISTA - SP
A30: REGIONAL SÃO JOÃO DA BOA VISTA - SP | B30: Divisão Poços de Caldas - MG
A31: REGIONAL SÃO JOÃO DA BOA VISTA - SP | B31: Divisao São Joao da Boa Vista - SP
A32: REGIONAL SÃO JOÃO DA BOA VISTA - SP | B32: Divisão Vargem Grande do Sul - SP
A33: REGIONAL SÃO JOÃO DA BOA VISTA - SP | B33: Divisão Águas da Prata - SP
A34: REGIONAL SÃO JOÃO DA BOA VISTA - SP | B34: Divisao Aguaí - SP
A36: REGIONAL CIRCUITO DAS ÁGUAS - SP
A37: REGIONAL CIRCUITO DAS ÁGUAS - SP | B37: Divisão Socorro - SP
A38: REGIONAL CIRCUITO DAS ÁGUAS - SP | B38: Divisao Águas de Lindóia - SP
A39: REGIONAL CIRCUITO DAS ÁGUAS - SP | B39: Divisão Lindóia - SP
A40: REGIONAL CIRCUITO DAS ÁGUAS - SP | B40: Divisão Amparo - SP
A41: REGIONAL CIRCUITO DAS ÁGUAS - SP | B41: Divisao Serra Negra - SP
A42: REGIONAL CIRCUITO DAS ÁGUAS - SP | B42: Divisão Monte Alegre do Sul - SP
A43: REGIONAL CIRCUITO DAS ÁGUAS - SP | B43: Divisão Monte Sião - MG
...

Sheet CMD VII
A1: VOLTAR
A2: Comando Regional VII | H2: *CMD REGIONAL VII*
A3: REGIONAL PRESIDENTE PRUDENTE | H3: =CAPA!C16 -> Mundial: Dabota
A4: REGIONAL PRESIDENTE PRUDENTE | B4: Divisão Dracena - SP | H4: =CAPA!C17 -> Cmd Brasil: Fiasch
A5: REGIONAL PRESIDENTE PRUDENTE | B5: Divisao Presidente Prudente - SP | H5: =CAPA!C18 -> Disciplina: Filipe
A6: REGIONAL PRESIDENTE PRUDENTE | B6: Divisao Presidente Venceslau - SP | H6: =CAPA!C19 -> Inteligência: Moreno
A7: REGIONAL PRESIDENTE PRUDENTE | B7: Divisao Tupi Paulista - SP | H7: =CAPA!C20 -> Adm Cmd: Mapola
A8: REGIONAL PRESIDENTE PRUDENTE | B8: Divisao Piraposinho- SP | H8: =CAPA!C21 -> Expansão: Tibão / Diego
A9: REGIONAL PRESIDENTE PRUDENTE | B9: Divisao Osvaldo Cruz - SP (Antiga Div. Bastos) | H9: =CAPA!C22 -> Comunicação: Chris Jr
A10: REGIONAL PRESIDENTE PRUDENTE | B10: Divisão Junqueirópolis - SP | H10: =CAPA!C23 -> Operacional: Ted / Sabion
A11: REGIONAL PRESIDENTE PRUDENTE | B11: Divisão Martinópolis - SP
A12: REGIONAL PRESIDENTE PRUDENTE | B12: Divisão Presidente Epitácio - SP
A14: REGIONAL SÃO JOSÉ DO RIO PRETO
A15: REGIONAL SÃO JOSÉ DO RIO PRETO | B15: Divisão Barretos - SP
A16: REGIONAL SÃO JOSÉ DO RIO PRETO | B16: Divisão Mirassol - SP
A17: REGIONAL SÃO JOSÉ DO RIO PRETO | B17: Divisao Olimpia - SP
A18: REGIONAL SÃO JOSÉ DO RIO PRETO | B18: Divisao São José do Rio Preto - SP
A19: REGIONAL SÃO JOSÉ DO RIO PRETO | B19: Divisão Fronteira - MG
A20: REGIONAL SÃO JOSÉ DO RIO PRETO | B20: Divisão São José do Rio Preto Norte - SP
A21: REGIONAL SÃO JOSÉ DO RIO PRETO | B21: Divisão São José do Rio Preto Leste - SP
A22: REGIONAL SÃO JOSÉ DO RIO PRETO | B22: Divisão Catanduva - SP
A23: REGIONAL SÃO JOSÉ DO RIO PRETO | B23: Divisão Guaraci - SP
A24: REGIONAL SÃO JOSÉ DO RIO PRETO | B24: Divisão Monte Aprazível - SP
A25: REGIONAL SÃO JOSÉ DO RIO PRETO | B25: Divisão José Bonifácio - SP
A26: REGIONAL SÃO JOSÉ DO RIO PRETO | B26: Divisão Icém - SP
... A31: REGIONAL SÃO JOSÉ DO RIO PRETO | B31: Divisão Bady Bassit - SP
A33: REGIONAL ANDRADINA
A34: REGIONAL ANDRADINA | B34: Divisão Andradina - SP
A35: REGIONAL ANDRADINA | B35: Divisão Ilha Solteira - SP
A36: REGIONAL ANDRADINA | B36: Divisão Castilho - SP
A37: REGIONAL ANDRADINA | B37: Divisão Pereira Barreto - SP
A38: REGIONAL ANDRADINA | B38: Divisão Murutinga do Sul - SP
A39: REGIONAL ANDRADINA | B39: Divisão Mirandópolis - SP
A41: REGIONAL ARAÇATUBA
A42: REGIONAL ARAÇATUBA | B42: Divisão Birigui - SP
A43: REGIONAL ARAÇATUBA | B43: Divisão Araçatuba - SP
A44: REGIONAL ARAÇATUBA | B44: Divisão Valparaiso - SP
A45: REGIONAL ARAÇATUBA | B45: Divisão Penápolis - SP
A46: REGIONAL ARAÇATUBA | B46: Divisão Piacatu - SP
A47: REGIONAL ARAÇATUBA | B47: Divisão Luiziânia - SP
...

Sheet CMD VIII
A1: VOLTAR
A2: Comando Regional VIII | C2: Comando Regional IX | H2: *CMD REGIONAL VIII*
A3: REGIONAL SP3 - LESTE | C3: REGIONAL BRASÍLIA I - DF | H3: =CAPA!D16 -> Mundial: Kefir
A4: REGIONAL SP3 - LESTE | B4: Divisão Extremo Leste - SP3 | C4: REGIONAL BRASILIA I - DF | D4: Divisão Brasília - DF | H4: =CAPA!D17 -> Cmd Brasil: Billhas
A5: REGIONAL SP3 - LESTE | B5: Divisão Extremo Oeste - SP3 | C5: REGIONAL BRASILIA I - DF | D5: Divisão Jardim Botânico - DF | H5: =CAPA!D18 -> Disciplina: K
A6: REGIONAL SP3 - LESTE | B6: Divisão Extremo Sul - SP3 | C6: REGIONAL BRASILIA I - DF | D6: Divisão Riacho Fundo - DF | H6: =CAPA!D19 -> Inteligência: Mau
A7: REGIONAL SP3 - LESTE | B7: Divisão Leste - SP3 | C7: REGIONAL BRASILIA I - DF | D7: Divisão São Sebastião - Df | H7: =CAPA!D20 -> Adm Cmd Br: Dead
A8: REGIONAL SP3 - LESTE | B8: Divisão Norte - SP3 | C8: REGIONAL BRASILIA I - DF | D8: Divisão Vicente Pires - DF | H8: =CAPA!D21 -> Expansão: Tibão / Giubne
A9: REGIONAL SP3 - LESTE | B9: Divisão Oeste - SP3 | C9: REGIONAL BRASILIA I - DF | D9: Divisão Guará - DF | H9: =CAPA!D22 -> Comunicação:
A10: REGIONAL SP3 - LESTE | B10: Divisão Sul - SP3 | C10: REGIONAL BRASILIA I - DF | D10: Divisão Taguatinga - DF | H10: =CAPA!D23 -> Operacional: Godoy / Alekão
A11: REGIONAL SP3 - LESTE | B11: Divisão Extremo Norte - SP3 | H11: =CAPA!D24 -> Armas: Agmon
A12: REGIONAL SP3 - LESTE | B12: Divisão Centro - SP3 | C12: REGIONAL BRASÍLIA II - DF
C13: REGIONAL BRASÍLIA II - DF | D13: Divisão Cidade Ocidental - GO
A14: REGIONAL SP5 | C14: REGIONAL BRASÍLIA II - DF | D14: Divisão Jardim Ingá - GO
A15: REGIONAL SP5 | B15: Divisão Extremo Leste - SP5 | C15: REGIONAL BRASÍLIA II - DF | D15: Divisão Luziânia - GO
A16: REGIONAL SP5 | B16: Divisão Extremo Norte - SP5 | C16: REGIONAL BRASÍLIA II - DF | D16: Divisão Novo Gama - GO
A17: REGIONAL SP5 | B17: Divisão Extremo Oeste 1 - SP5 | C17: REGIONAL BRASÍLIA II - DF | D17: Divisão Paracatu - MG
A18: REGIONAL SP5 | B18: Divisão Extremo Sul - SP5 | C18: REGIONAL BRASÍLIA II - DF | D18: Divisão Valparaiso - GO
A19: REGIONAL SP5 | B19: Divisão Norte - SP5 | C19: REGIONAL BRASÍLIA II - DF | D19: Divisão Jardim ABC - GO
A20: REGIONAL SP5 | B20: Divisão Oeste - SP5 | C20: REGIONAL BRASÍLIA II - DF | D20: Divisão Cristalina - GO
A21: REGIONAL SP5 | B21: Divisão Sul - SP5 | C21: REGIONAL BRASÍLIA II - DF | D21: Divisão Unaí - MG
A22: REGIONAL SP5 | B22: Divisão Extremo Oeste 2 - SP5
A23: REGIONAL SP5 | B23: Divisão Extremo Leste 2 - SP5 | C23: REGIONAL BRASÍLIA III - DF
C24: REGIONAL BRASÍLIA III - DF | D24: Divisão Águas Lindas - GO
A25: REGIONAL SP10 | C25: REGIONAL BRASÍLIA III - DF | D25: Divisão Ceilândia - DF
A26: REGIONAL SP10 | B26: Divisão Norte - SP10 | C26: REGIONAL BRASÍLIA III - DF | D26: Divisão Gama - DF
A27: REGIONAL SP10 | B27: Divisão Sul - SP10 | C27: REGIONAL BRASÍLIA III - DF | D27: Divisão Recanto das Emas - DF
A28: REGIONAL SP10 | B28: Divisão Leste - SP10 | C28: REGIONAL BRASÍLIA III - DF | D28: Divisão Samambaia - DF
A29: REGIONAL SP10 | B29: Divisão Oeste - SP10 | C29: REGIONAL BRASÍLIA III - DF | D29: Divisão Santa Maria - DF
A30: REGIONAL SP10 | B30: Divisão Extremo Norte - SP10
A31: REGIONAL SP10 | B31: Divisão Extremo Sul - SP10 | C31: REGIONAL BRASÍLIA IV- DF
A32: REGIONAL SP10 | B32: Divisão Extremo Oeste - SP10 | C32: REGIONAL BRASÍLIA IV - DF | D32: Divisão Formosa - GO
A33: REGIONAL SP10 | B33: Divisão Extremo Leste - SP10 | C33: REGIONAL BRASÍLIA IV - DF | D33: Divisão Paranoá - DF
A34: REGIONAL SP10 | B34: Divisão Centro - SP10 | C34: REGIONAL BRASÍLIA IV - DF | D34: Divisão Planaltina - GO
C35: REGIONAL BRASÍLIA IV - DF | D35: Divisão Planaltina - DF
A36: REGIONAL SP13 | C36: REGIONAL BRASÍLIA IV - DF | D36: Divisão Sobradinho - DF
A37: REGIONAL SP13 | B37: Divisão Leste - SP13 | C37: REGIONAL BRASÍLIA IV - DF | D37: Divisão Unaí - MG
A38: REGIONAL SP13 | B38: Divisão Oeste - SP13
A39: REGIONAL SP13 | B39: Divisão Norte - SP13 | C39: REGIONAL TOCANTINS
A40: REGIONAL SP13 | B40: Divisão Centro - SP13 | C40: REGIONAL TOCANTINS | D40: Divisão Araguaína - TO
...

Sheet CMD IX
A1: VOLTAR
A2: Comando Regional IX | D2: *CMD REGIONAL IX*
A3: REGIONAL BRASÍLIA I - DF | D3: =CAPA!E16 -> Mundial: Naruê
A4: REGIONAL BRASILIA I - DF | B4: Divisão Brasília - DF | D4: =CAPA!E17 -> Cmd Brasil: Shodan
A5: REGIONAL BRASILIA I - DF | B5: Divisão Jardim Botânico - DF | D5: =CAPA!E18 -> Disciplina: Henrique
A6: REGIONAL BRASILIA I - DF | B6: Divisão Riacho Fundo - DF | D6: =CAPA!E19 -> Inteligência: Demétrio
A7: REGIONAL BRASILIA I - DF | B7: Divisão São Sebastião - Df | D7: =CAPA!E20 -> Adm Cmd: Hugo Melo
A8: REGIONAL BRASILIA I - DF | B8: Divisão Vicente Pires - DF | D8: =CAPA!E21 -> Expansão: Tibão / Pendente
A9: REGIONAL BRASILIA I - DF | B9: Divisão Guará - DF | D9: =CAPA!E22 -> Comunicação: Cruvinel
A10: REGIONAL BRASILIA I - DF | B10: Divisão Taguatinga - DF | D10: =CAPA!E23 -> Operacional: Ted / Pedro
D11: =CAPA!E24 -> Armas: Bbz
A12: REGIONAL BRASÍLIA II - DF
A13: REGIONAL BRASÍLIA II - DF | B13: Divisão Cidade Ocidental - GO
A14: REGIONAL BRASÍLIA II - DF | B14: Divisão Jardim Ingá - GO
A15: REGIONAL BRASÍLIA II - DF | B15: Divisão Luziânia - GO
A16: REGIONAL BRASÍLIA II - DF | B16: Divisão Novo Gama - GO
A17: REGIONAL BRASÍLIA II - DF | B17: Divisão Paracatu - MG
A18: REGIONAL BRASÍLIA II - DF | B18: Divisão Valparaiso - GO
A19: REGIONAL BRASÍLIA II - DF | B19: Divisão Jardim ABC - GO
A20: REGIONAL BRASÍLIA II - DF | B20: Divisão Cristalina - GO
A22: REGIONAL BRASÍLIA III - DF
A23: REGIONAL BRASÍLIA III - DF | B23: Divisão Águas Lindas - GO
A24: REGIONAL BRASÍLIA III - DF | B24: Divisão Ceilândia - DF
A25: REGIONAL BRASÍLIA III - DF | B25: Divisão Gama - DF
A26: REGIONAL BRASÍLIA III - DF | B26: Divisão Recanto das Emas - DF
A27: REGIONAL BRASÍLIA III - DF | B27: Divisão Samambaia - DF
A28: REGIONAL BRASÍLIA III - DF | B28: Divisão Santa Maria - DF
A30: REGIONAL BRASÍLIA IV- DF
A31: REGIONAL BRASÍLIA IV - DF | B31: Divisão Formosa - GO
A32: REGIONAL BRASÍLIA IV - DF | B32: Divisão Paranoá - DF
A33: REGIONAL BRASÍLIA IV - DF | B33: Divisão Planaltina - GO
A34: REGIONAL BRASÍLIA IV - DF | B34: Divisão Planaltina - DF
A35: REGIONAL BRASÍLIA IV - DF | B35: Divisão Sobradinho - DF
A36: REGIONAL BRASÍLIA IV - DF | B36: Divisão Unaí - MG
A38: REGIONAL TOCANTINS
A39: REGIONAL TOCANTINS | B39: Divisão Araguaína - TO
A40: REGIONAL TOCANTINS | B40: Divisão Gurupi Sul - TO
A41: REGIONAL TOCANTINS | B41: Divisão Palmas - TO
A42: REGIONAL TOCANTINS | B42: Divisão Paraiso - TO
A43: REGIONAL TOCANTINS | B43: Divisão Gurupi Norte - TO

Sheet CMD X
A1: VOLTAR
A2: Comando Regional X | D2: *CMD REGIONAL X*
A3: REGIONAL OSASCO 1 - SP | D3: =CAPA!F16 -> Mundial: Roney
A4: REGIONAL OSASCO 1 - SP | B4: Divisão Osasco 1 Centro - SP | D4: =CAPA!F17 -> Cmd Brasil: Clayton
A5: REGIONAL OSASCO 1 - SP | B5: Divisão Osasco 1 Extremo Oeste - SP | D5: =CAPA!F18 -> Disciplina: Ching
A6: REGIONAL OSASCO 1 - SP | B6: Divisão Osasco 1 Extremo Sul - SP | D6: =CAPA!F19 -> Inteligência: Fico
A7: REGIONAL OSASCO 1 - SP | B7: Divisão Osasco 1 Leste - SP | D7: =CAPA!F20 -> Adm Cmd: Cabelo
D8: =CAPA!F21 -> Expansão: Tibão / Carvalho
A9: REGIONAL OSASCO 2 - SP | D9: =CAPA!F22 -> Comunicação: Chris Jr
A10: REGIONAL OSASCO 2 - SP | B10: Divisão Osasco 2 Centro Velho - SP | D10: =CAPA!F23 -> Operacional: Munrah
A11: REGIONAL OSASCO 2 - SP | B11: Divisão Osasco 2 Norte - SP | D11: =CAPA!F24 -> Armas: Coyote
A12: REGIONAL OSASCO 2 - SP | B12: Divisão Osasco 2 Oeste - SP
A13: REGIONAL OSASCO 2 - SP | B13: Divisão Osasco 2 Extremo Leste - SP (Antiga Leste)
A15: REGIONAL OSASCO 3 - SP
A16: REGIONAL OSASCO 3 - SP | B16: Divisão Osasco 3 Centro - SP
A17: REGIONAL OSASCO 3 - SP | B17: Divisão Osasco 3 Oeste - SP
A18: REGIONAL OSASCO 3 - SP | B18: Divisão Osasco 3 Extremo Norte - SP
A19: REGIONAL OSASCO 3 - SP | B19: Divisão Osasco 3 Sul - SP
A20: REGIONAL OSASCO 3 - SP | B20: Divisão Osasco 3 Norte - SP
A21: REGIONAL OSASCO 3 - SP | B21: Divisão Osasco 3 Extremo Oeste - SP
A23: REGIONAL OSASCO 4 - SP
A24: REGIONAL OSASCO 4 - SP | B24: Divisão Osasco 4 Extremo Leste - SP
A25: REGIONAL OSASCO 4 - SP | B25: Divisão Osasco 4 Sul - SP
A26: REGIONAL OSASCO 4 - SP | B26: Divisão Osasco 4 Oeste - SP (Antiga X-Leste)
A27: REGIONAL OSASCO 4 - SP | B27: Divisão Osasco 4 Norte - SP
A29: REGIONAL OSASCO 5 - SP
A30: REGIONAL OSASCO 5 - SP | B30: Divisão Osasco 5 Extremo Oeste - SP
A31: REGIONAL OSASCO 5 - SP | B31: Divisão Osasco 5 Leste - SP (Antiga Oeste)
A32: REGIONAL OSASCO 5 - SP | B32: Divisão Osasco 5 Centro - SP (Antiga X-Oeste)

Sheet CMD XI
A1: VOLTAR
A2: Comando Regional XI | C2: Comando Regional XII
A3: REGIONAL ABC1 | C3: REGIONAL BELO HORIZONTE
A4: REGIONAL ABC1 | B4: Divisão Riacho Grande - SP | C4: REGIONAL BELO HORIZONTE | D4: Divisao Belo Horizonte - MG
A5: REGIONAL ABC1 | B5: Divisão São Bernardo do Campo Norte - SP | C5: REGIONAL BELO HORIZONTE | D5: Divisão Betim - MG
A6: REGIONAL ABC1 | B6: Divisão São Bernardo do Campo Sul - SP | C6: REGIONAL BELO HORIZONTE | D6: Divisao Belo Horizonte Norte - MG
A7: REGIONAL ABC1 | B7: Divisão São Bernardo do Campo Oeste - SP | C7: REGIONAL BELO HORIZONTE | D7: Divisão Igarapé - MG
A8: REGIONAL ABC1 | B8: Divisão São Bernardo do Centro - SP | C8: REGIONAL BELO HORIZONTE | D8: Divisão Ibirité - MG
A9: REGIONAL ABC1 | B9: Divisão São Bernardo do Campo Leste - SP
A10: REGIONAL ABC1 | B10: Divisão São Bernardo do Campo Extremo Norte - SP | C10: REGIONAL NORTE DE MINAS - MG
C11: REGIONAL NORTE DE MINAS - MG | D11: Divisão Curvelo Centro - MG
A12: REGIONAL ABC2 | C12: REGIONAL NORTE DE MINAS - MG | D12: Divisão Curvelo Sul - MG
A13: REGIONAL ABC2 | B13: Divisão Santo André Centro - SP | C13: REGIONAL NORTE DE MINAS - MG | D13: Divisão Montes Claros - MG
A14: REGIONAL ABC2 | B14: Divisão Santo André Sul - SP | C14: REGIONAL NORTE DE MINAS - MG | D14: Divisão Pirapora - MG
A15: REGIONAL ABC2 | B15: Divisão Santo André Extremo Norte - SP | C15: REGIONAL NORTE DE MINAS - MG | D15: Divisão Sete Lagoas - MG
A16: REGIONAL ABC2 | B16: Divisão Santo André Extremo Sul - SP | C16: REGIONAL NORTE DE MINAS - MG | D16: Divisão Januária - MG
A17: REGIONAL ABC2 | B17: Divisão Santo André Norte - SP | C17: REGIONAL NORTE DE MINAS - MG | D17: Divisão Capelinha - MG
A18: REGIONAL ABC2 | B18: Divisão Santo André Leste - SP | C18: REGIONAL NORTE DE MINAS - MG | D18: Divisão Felixlândia - MG
A19: REGIONAL ABC2 | B19: Divisão Santo André Oeste - SP | C19: REGIONAL NORTE DE MINAS - MG | D19: Divisão Inimutaba - MG
C20: REGIONAL NORTE DE MINAS - MG | D20: Divisão Corinto - MG
A21: REGIONAL ABC6 | C21: REGIONAL NORTE DE MINAS - MG | D21: Divisão Turmalina - MG
A22: REGIONAL ABC6 | B22: Divisão São Caetano do Sul Centro - SP | C22: REGIONAL NORTE DE MINAS - MG | D22: Divisão Janaúba - MG
A23: REGIONAL ABC6 | B23: Divisão São Caetano do Sul Leste - SP
A24: REGIONAL ABC6 | B24: Divisão São Caetano do Sul Sul - SP | C24: REGIONAL OESTE DE MINAS - MG
A25: REGIONAL ABC6 | B25: Divisão São Caetano do Sul Oeste - SP | C25: REGIONAL OESTE DE MINAS - MG | D25: Divisão Betim Oeste - MG
C26: REGIONAL OESTE DE MINAS - MG | D26: Divisão Itaúna - MG
A27: REGIONAL ABC7 | C27: REGIONAL OESTE DE MINAS - MG | D27: Divisão Papagaios - MG
A28: REGIONAL ABC7 | B28: Divisão Diadema Sul - SP | C28: REGIONAL OESTE DE MINAS - MG | D28: Divisão Pará de Minas - MG
A29: REGIONAL ABC7 | B29: Divisão Diadema Norte - SP | C29: REGIONAL OESTE DE MINAS - MG | D29: Divisão Divinópolis - MG
A30: REGIONAL ABC7 | B30: Divisão Diadema Leste - SP | C30: REGIONAL OESTE DE MINAS - MG | D30: Divisão Mateus Leme - MG
A31: REGIONAL ABC7 | B31: Divisão Diadema Oeste - SP | C31: REGIONAL OESTE DE MINAS - MG | D31: Divisão Nova Serrana - MG
C32: REGIONAL OESTE DE MINAS - MG | D32: Divisão Cláudio - MG

Sheet CMD XII
A1: VOLTAR
A2: Comando Regional XII | D2: *CMD REGIONAL XII*
A3: REGIONAL BELO HORIZONTE | D3: =CAPA!C26 -> Representante: Véio
A4: REGIONAL BELO HORIZONTE | B4: Divisao Belo Horizonte - MG | D4: =CAPA!C27 -> Cmd Brasil: Almeida
A5: REGIONAL BELO HORIZONTE | B5: Divisão Betim - MG | D5: =CAPA!C28 -> Disciplina: Cidão
A6: REGIONAL BELO HORIZONTE | B6: Divisao Belo Horizonte Norte - MG | D6: =CAPA!C29 -> Inteligência: Dias
A7: REGIONAL BELO HORIZONTE | B7: Divisão Igarapé - MG | D7: =CAPA!C30 -> Adm Cmd: Brow
A8: REGIONAL BELO HORIZONTE | B8: Divisão Ibirité - MG | D8: =CAPA!C31 -> Expansão: Tibão / Sniper
A9: REGIONAL BELO HORIZONTE | B9: Divisão Betim Leste - MG | D9: =CAPA!C32 -> Comunicação: Cruvinel
D10: =CAPA!C33 -> Operacional: Ted / Sicário
A11: REGIONAL NORTE DE MINAS - MG | D11: =CAPA!C34 -> Armas: Rachid
A12: REGIONAL NORTE DE MINAS - MG | B12: Divisão Curvelo Centro - MG
A13: REGIONAL NORTE DE MINAS - MG | B13: Divisão Curvelo Sul - MG
A14: REGIONAL NORTE DE MINAS - MG | B14: Divisão Montes Claros - MG
A15: REGIONAL NORTE DE MINAS - MG | B15: Divisão Pirapora - MG
A16: REGIONAL NORTE DE MINAS - MG | B16: Divisão Sete Lagoas - MG
A17: REGIONAL NORTE DE MINAS - MG | B17: Divisão Januária - MG
A18: REGIONAL NORTE DE MINAS - MG | B18: Divisão Capelinha - MG
A19: REGIONAL NORTE DE MINAS - MG | B19: Divisão Felixlândia - MG
A20: REGIONAL NORTE DE MINAS - MG | B20: Divisão Inimutaba - MG
A21: REGIONAL NORTE DE MINAS - MG | B21: Divisão Corinto - MG
A22: REGIONAL NORTE DE MINAS - MG | B22: Divisão Turmalina - MG
A23: REGIONAL NORTE DE MINAS - MG | B23: Divisão Janaúba - MG
A25: REGIONAL OESTE DE MINAS - MG
A26: REGIONAL OESTE DE MINAS - MG | B26: Divisão Betim Oeste - MG
A27: REGIONAL OESTE DE MINAS - MG | B27: Divisão Itaúna - MG
A28: REGIONAL OESTE DE MINAS - MG | B28: Divisão Papagaios - MG
A29: REGIONAL OESTE DE MINAS - MG | B29: Divisão Pará de Minas - MG
A30: REGIONAL OESTE DE MINAS - MG | B30: Divisão Divinópolis - MG
A31: REGIONAL OESTE DE MINAS - MG | B31: Divisão Mateus Leme - MG
A32: REGIONAL OESTE DE MINAS - MG | B32: Divisão Nova Serrana - MG
A33: REGIONAL OESTE DE MINAS - MG | B33: Divisão Cláudio - MG

Sheet CMD XIII
A1: VOLTAR
A2: Comando Regional XIII | C2: Comando Regional XIV
A3: REGIONAL CHAPECÓ | C3: REGIONAL SOROCABA
A4: REGIONAL CHAPECÓ | B4: Divisão Chapecó - SC | C4: REGIONAL SOROCABA | D4: Divisão Sorocaba Centro - SP
A5: REGIONAL CHAPECÓ | B5: Divisão Ponte Serrada - SC | C5: REGIONAL SOROCABA | D5: Divisão Sorocaba Norte - SP
A6: REGIONAL CHAPECÓ | B6: Divisão Xanxerê - SC | C6: REGIONAL SOROCABA | D6: Divisão Sorocaba Oeste - SP
A7: REGIONAL CHAPECÓ | B7: Divisão Oeste Catarinense - SC | C7: REGIONAL SOROCABA | D7: Divisão Votorantim - SP
A8: REGIONAL CHAPECÓ | B8: Divisão Norte Gaúcho - SC | C8: REGIONAL SOROCABA | D8: Divisão Sorocaba Sul - SP
A9: REGIONAL CHAPECÓ | B9: Divisão São Lourenço do Oeste - SC | C9: REGIONAL SOROCABA | D9: Divisão Aparecidinha - SP
A10: REGIONAL CHAPECÓ | B10: Divisão Passo Fundo - SC | C10: REGIONAL SOROCABA | D10: Divisão Éden - SP
C11: REGIONAL SOROCABA | D11: Divisão Votorantim Leste - SP
A12: REGIONAL CONCÓRDIA - SC | C12: REGIONAL SOROCABA | D12: Divisão Brigadeiro Tobias - SP
A13: REGIONAL CONCÓRDIA - SC | B13: Divisão Caçador - SC | C13: REGIONAL SOROCABA | D13: Divisão Sorocaba Leste - SP
A14: REGIONAL CONCÓRDIA - SC | B14: Divisão Concórdia - SC
A15: REGIONAL CONCÓRDIA - SC | B15: Divisão Videira - SC | C15: REGIONAL ITU - SP
A16: REGIONAL CONCÓRDIA - SC | B16: Divisão Seara - SC | C16: REGIONAL ITU - SP | D16: Divisão Itú - SP
A17: REGIONAL CONCÓRDIA - SC | B17: Divisão Vale do Rio do Peixe - SC | C17: REGIONAL ITU - SP | D17: Divisão Porto Feliz - SP
C18: REGIONAL ITU - SP | D18: Divisão Salto - SP
A19: REGIONAL PORTO ALEGRE | C19: REGIONAL ITU - SP | D19: Divisão Indaiatuba - SP
A20: REGIONAL PORTO ALEGRE | B20: Divisão Alvorada - RS | C20: REGIONAL ITU - SP | D20: Divisão Boituva - SP
A21: REGIONAL PORTO ALEGRE | B21: Divisão Litoral Gaúcho - RS | C21: REGIONAL ITU - SP | D21: Divisão Elias Fausto - SP
A22: REGIONAL PORTO ALEGRE | B22: Divisão Porto Alegre - RS | C22: REGIONAL ITU - SP | D22: Divisão Salto Norte - SP
A23: REGIONAL PORTO ALEGRE | B23: Divisão Extremo Sul - RS | C23: REGIONAL ITU - SP | D23: Divisão Indaiatuba Norte - SP
A24: REGIONAL PORTO ALEGRE | B24: Divisão Vale dos Sinos - RS
A25: REGIONAL PORTO ALEGRE | B25: Divisão Porto Alegre Norte - RS | C25: REGIONAL IBIÚNA - SP
A26: REGIONAL PORTO ALEGRE | B26: Divisão Porto Alegre Sul - RS | C26: REGIONAL IBIÚNA - SP | D26: Divisão Ibiúna - SP
A27: REGIONAL PORTO ALEGRE | B27: Divisão Carbonífera - RS | C27: REGIONAL IBIÚNA - SP | D27: Divisão São Roque - SP
A28: REGIONAL PORTO ALEGRE | B28: Divisão Vale do Gravataí - RS | C28: REGIONAL IBIÚNA - SP | D28: Divisão Ibiúna Leste - SP
C29: REGIONAL IBIÚNA - SP | D29: Divisão São Roque Norte - SP
A30: REGIONAL SANTA MARIA - RS | C30: REGIONAL IBIÚNA - SP | D30: Divisão São Roque Leste - SP
A31: REGIONAL SANTA MARIA - RS | B31: Divisão Santa Maria - RS
A32: REGIONAL SANTA MARIA - RS | B32: Divisão São Gabriel - RS | C32: REGIONAL MAIRINQUE - SP
A33: REGIONAL SANTA MARIA - RS | B33: Divisão Três Passos - RS | C33: REGIONAL MAIRINQUE - SP | D33: Divisão Mairinque - SP
